[2023-07-12 06:21:53,401] {taskinstance.py:877} INFO - Dependencies all met for <TaskInstance: online_payment_dag.store_to_gcs 2023-07-12T06:20:36.939092+00:00 [queued]>
[2023-07-12 06:21:53,457] {taskinstance.py:877} INFO - Dependencies all met for <TaskInstance: online_payment_dag.store_to_gcs 2023-07-12T06:20:36.939092+00:00 [queued]>
[2023-07-12 06:21:53,458] {taskinstance.py:1068} INFO - 
--------------------------------------------------------------------------------
[2023-07-12 06:21:53,458] {taskinstance.py:1069} INFO - Starting attempt 1 of 1
[2023-07-12 06:21:53,458] {taskinstance.py:1070} INFO - 
--------------------------------------------------------------------------------
[2023-07-12 06:21:53,503] {taskinstance.py:1089} INFO - Executing <Task(LocalFilesystemToGCSOperator): store_to_gcs> on 2023-07-12T06:20:36.939092+00:00
[2023-07-12 06:21:53,509] {standard_task_runner.py:52} INFO - Started process 54 to run task
[2023-07-12 06:21:53,513] {standard_task_runner.py:76} INFO - Running: ['airflow', 'tasks', 'run', 'online_payment_dag', 'store_to_gcs', '2023-07-12T06:20:36.939092+00:00', '--job-id', '37', '--pool', 'default_pool', '--raw', '--subdir', 'DAGS_FOLDER/online_payment_dag.py', '--cfg-path', '/tmp/tmplwga7v3q', '--error-file', '/tmp/tmpnl5oy4j5']
[2023-07-12 06:21:53,514] {standard_task_runner.py:77} INFO - Job 37: Subtask store_to_gcs
[2023-07-12 06:21:53,622] {logging_mixin.py:104} INFO - Running <TaskInstance: online_payment_dag.store_to_gcs 2023-07-12T06:20:36.939092+00:00 [running]> on host a5b832011b5f
[2023-07-12 06:21:53,702] {taskinstance.py:1281} INFO - Exporting the following env vars:
AIRFLOW_CTX_DAG_EMAIL=datokza@gmail.com
AIRFLOW_CTX_DAG_OWNER=okza
AIRFLOW_CTX_DAG_ID=online_payment_dag
AIRFLOW_CTX_TASK_ID=store_to_gcs
AIRFLOW_CTX_EXECUTION_DATE=2023-07-12T06:20:36.939092+00:00
AIRFLOW_CTX_DAG_RUN_ID=manual__2023-07-12T06:20:36.939092+00:00
[2023-07-12 06:21:54,085] {gcs.py:445} ERROR - Upload attempt of object: online_payment.csv from online_payment.csv has failed. Attempt: 1, max 1.
[2023-07-12 06:21:54,086] {taskinstance.py:1482} ERROR - Task failed with exception
Traceback (most recent call last):
  File "/home/airflow/.local/lib/python3.8/site-packages/google/cloud/storage/blob.py", line 2353, in upload_from_file
    created_json = self._do_upload(
  File "/home/airflow/.local/lib/python3.8/site-packages/google/cloud/storage/blob.py", line 2175, in _do_upload
    response = self._do_multipart_upload(
  File "/home/airflow/.local/lib/python3.8/site-packages/google/cloud/storage/blob.py", line 1737, in _do_multipart_upload
    response = upload.transmit(
  File "/home/airflow/.local/lib/python3.8/site-packages/google/resumable_media/requests/upload.py", line 149, in transmit
    self._process_response(response)
  File "/home/airflow/.local/lib/python3.8/site-packages/google/resumable_media/_upload.py", line 116, in _process_response
    _helpers.require_status_code(response, (http_client.OK,), self._get_status_code)
  File "/home/airflow/.local/lib/python3.8/site-packages/google/resumable_media/_helpers.py", line 99, in require_status_code
    raise common.InvalidResponse(
google.resumable_media.common.InvalidResponse: ('Request failed with status code', 403, 'Expected one of', <HTTPStatus.OK: 200>)

During handling of the above exception, another exception occurred:

Traceback (most recent call last):
  File "/home/airflow/.local/lib/python3.8/site-packages/airflow/models/taskinstance.py", line 1138, in _run_raw_task
    self._prepare_and_execute_task_with_callbacks(context, task)
  File "/home/airflow/.local/lib/python3.8/site-packages/airflow/models/taskinstance.py", line 1311, in _prepare_and_execute_task_with_callbacks
    result = self._execute_task(context, task_copy)
  File "/home/airflow/.local/lib/python3.8/site-packages/airflow/models/taskinstance.py", line 1341, in _execute_task
    result = task_copy.execute(context=context)
  File "/home/airflow/.local/lib/python3.8/site-packages/airflow/providers/google/cloud/transfers/local_to_gcs.py", line 132, in execute
    hook.upload(
  File "/home/airflow/.local/lib/python3.8/site-packages/airflow/providers/google/cloud/hooks/gcs.py", line 479, in upload
    _call_with_retry(
  File "/home/airflow/.local/lib/python3.8/site-packages/airflow/providers/google/cloud/hooks/gcs.py", line 452, in _call_with_retry
    raise e
  File "/home/airflow/.local/lib/python3.8/site-packages/airflow/providers/google/cloud/hooks/gcs.py", line 441, in _call_with_retry
    f()
  File "/home/airflow/.local/lib/python3.8/site-packages/google/cloud/storage/blob.py", line 2480, in upload_from_filename
    self.upload_from_file(
  File "/home/airflow/.local/lib/python3.8/site-packages/google/cloud/storage/blob.py", line 2369, in upload_from_file
    _raise_from_invalid_response(exc)
  File "/home/airflow/.local/lib/python3.8/site-packages/google/cloud/storage/blob.py", line 4066, in _raise_from_invalid_response
    raise exceptions.from_http_status(response.status_code, message, response=response)
google.api_core.exceptions.Forbidden: 403 POST https://storage.googleapis.com/upload/storage/v1/b/airflowdf/o?uploadType=multipart: {
  "error": {
    "code": 403,
    "message": "The billing account for the owning project is disabled in state absent",
    "errors": [
      {
        "message": "The billing account for the owning project is disabled in state absent",
        "domain": "global",
        "reason": "accountDisabled",
        "locationType": "header",
        "location": "Authorization"
      }
    ]
  }
}
: ('Request failed with status code', 403, 'Expected one of', <HTTPStatus.OK: 200>)
[2023-07-12 06:21:54,090] {taskinstance.py:1525} INFO - Marking task as FAILED. dag_id=online_payment_dag, task_id=store_to_gcs, execution_date=20230712T062036, start_date=20230712T062153, end_date=20230712T062154
[2023-07-12 06:21:54,105] {configuration.py:352} WARNING - section/key [smtp/smtp_user] not found in config
[2023-07-12 06:21:54,106] {email.py:184} INFO - Email alerting: attempt 1
[2023-07-12 06:21:54,108] {configuration.py:352} WARNING - section/key [smtp/smtp_user] not found in config
[2023-07-12 06:21:54,108] {email.py:184} INFO - Email alerting: attempt 1
[2023-07-12 06:21:54,109] {taskinstance.py:1538} ERROR - Failed to send email to: datokza@gmail.com
[2023-07-12 06:21:54,109] {taskinstance.py:1539} ERROR - [Errno 99] Cannot assign requested address
Traceback (most recent call last):
  File "/home/airflow/.local/lib/python3.8/site-packages/google/cloud/storage/blob.py", line 2353, in upload_from_file
    created_json = self._do_upload(
  File "/home/airflow/.local/lib/python3.8/site-packages/google/cloud/storage/blob.py", line 2175, in _do_upload
    response = self._do_multipart_upload(
  File "/home/airflow/.local/lib/python3.8/site-packages/google/cloud/storage/blob.py", line 1737, in _do_multipart_upload
    response = upload.transmit(
  File "/home/airflow/.local/lib/python3.8/site-packages/google/resumable_media/requests/upload.py", line 149, in transmit
    self._process_response(response)
  File "/home/airflow/.local/lib/python3.8/site-packages/google/resumable_media/_upload.py", line 116, in _process_response
    _helpers.require_status_code(response, (http_client.OK,), self._get_status_code)
  File "/home/airflow/.local/lib/python3.8/site-packages/google/resumable_media/_helpers.py", line 99, in require_status_code
    raise common.InvalidResponse(
google.resumable_media.common.InvalidResponse: ('Request failed with status code', 403, 'Expected one of', <HTTPStatus.OK: 200>)

During handling of the above exception, another exception occurred:

Traceback (most recent call last):
  File "/home/airflow/.local/lib/python3.8/site-packages/airflow/models/taskinstance.py", line 1138, in _run_raw_task
    self._prepare_and_execute_task_with_callbacks(context, task)
  File "/home/airflow/.local/lib/python3.8/site-packages/airflow/models/taskinstance.py", line 1311, in _prepare_and_execute_task_with_callbacks
    result = self._execute_task(context, task_copy)
  File "/home/airflow/.local/lib/python3.8/site-packages/airflow/models/taskinstance.py", line 1341, in _execute_task
    result = task_copy.execute(context=context)
  File "/home/airflow/.local/lib/python3.8/site-packages/airflow/providers/google/cloud/transfers/local_to_gcs.py", line 132, in execute
    hook.upload(
  File "/home/airflow/.local/lib/python3.8/site-packages/airflow/providers/google/cloud/hooks/gcs.py", line 479, in upload
    _call_with_retry(
  File "/home/airflow/.local/lib/python3.8/site-packages/airflow/providers/google/cloud/hooks/gcs.py", line 452, in _call_with_retry
    raise e
  File "/home/airflow/.local/lib/python3.8/site-packages/airflow/providers/google/cloud/hooks/gcs.py", line 441, in _call_with_retry
    f()
  File "/home/airflow/.local/lib/python3.8/site-packages/google/cloud/storage/blob.py", line 2480, in upload_from_filename
    self.upload_from_file(
  File "/home/airflow/.local/lib/python3.8/site-packages/google/cloud/storage/blob.py", line 2369, in upload_from_file
    _raise_from_invalid_response(exc)
  File "/home/airflow/.local/lib/python3.8/site-packages/google/cloud/storage/blob.py", line 4066, in _raise_from_invalid_response
    raise exceptions.from_http_status(response.status_code, message, response=response)
google.api_core.exceptions.Forbidden: 403 POST https://storage.googleapis.com/upload/storage/v1/b/airflowdf/o?uploadType=multipart: {
  "error": {
    "code": 403,
    "message": "The billing account for the owning project is disabled in state absent",
    "errors": [
      {
        "message": "The billing account for the owning project is disabled in state absent",
        "domain": "global",
        "reason": "accountDisabled",
        "locationType": "header",
        "location": "Authorization"
      }
    ]
  }
}
: ('Request failed with status code', 403, 'Expected one of', <HTTPStatus.OK: 200>)

During handling of the above exception, another exception occurred:

Traceback (most recent call last):
  File "/home/airflow/.local/lib/python3.8/site-packages/airflow/models/taskinstance.py", line 1881, in email_alert
    send_email(self.task.email, subject, html_content)
  File "/home/airflow/.local/lib/python3.8/site-packages/airflow/utils/email.py", line 52, in send_email
    return backend(
  File "/home/airflow/.local/lib/python3.8/site-packages/airflow/utils/email.py", line 97, in send_email_smtp
    send_mime_email(e_from=smtp_mail_from, e_to=recipients, mime_msg=msg, dryrun=dryrun)
  File "/home/airflow/.local/lib/python3.8/site-packages/airflow/utils/email.py", line 186, in send_mime_email
    conn = _get_smtp_connection(smtp_host, smtp_port, smtp_timeout, smtp_ssl)
  File "/home/airflow/.local/lib/python3.8/site-packages/airflow/utils/email.py", line 220, in _get_smtp_connection
    else smtplib.SMTP(host=host, port=port, timeout=timeout)
  File "/usr/local/lib/python3.8/smtplib.py", line 255, in __init__
    (code, msg) = self.connect(host, port)
  File "/usr/local/lib/python3.8/smtplib.py", line 339, in connect
    self.sock = self._get_socket(host, port, self.timeout)
  File "/usr/local/lib/python3.8/smtplib.py", line 310, in _get_socket
    return socket.create_connection((host, port), timeout,
  File "/usr/local/lib/python3.8/socket.py", line 808, in create_connection
    raise err
  File "/usr/local/lib/python3.8/socket.py", line 796, in create_connection
    sock.connect(sa)
OSError: [Errno 99] Cannot assign requested address

During handling of the above exception, another exception occurred:

Traceback (most recent call last):
  File "/home/airflow/.local/lib/python3.8/site-packages/airflow/models/taskinstance.py", line 1536, in handle_failure
    self.email_alert(error)
  File "/home/airflow/.local/lib/python3.8/site-packages/airflow/models/taskinstance.py", line 1883, in email_alert
    send_email(self.task.email, subject, html_content_err)
  File "/home/airflow/.local/lib/python3.8/site-packages/airflow/utils/email.py", line 52, in send_email
    return backend(
  File "/home/airflow/.local/lib/python3.8/site-packages/airflow/utils/email.py", line 97, in send_email_smtp
    send_mime_email(e_from=smtp_mail_from, e_to=recipients, mime_msg=msg, dryrun=dryrun)
  File "/home/airflow/.local/lib/python3.8/site-packages/airflow/utils/email.py", line 186, in send_mime_email
    conn = _get_smtp_connection(smtp_host, smtp_port, smtp_timeout, smtp_ssl)
  File "/home/airflow/.local/lib/python3.8/site-packages/airflow/utils/email.py", line 220, in _get_smtp_connection
    else smtplib.SMTP(host=host, port=port, timeout=timeout)
  File "/usr/local/lib/python3.8/smtplib.py", line 255, in __init__
    (code, msg) = self.connect(host, port)
  File "/usr/local/lib/python3.8/smtplib.py", line 339, in connect
    self.sock = self._get_socket(host, port, self.timeout)
  File "/usr/local/lib/python3.8/smtplib.py", line 310, in _get_socket
    return socket.create_connection((host, port), timeout,
  File "/usr/local/lib/python3.8/socket.py", line 808, in create_connection
    raise err
  File "/usr/local/lib/python3.8/socket.py", line 796, in create_connection
    sock.connect(sa)
OSError: [Errno 99] Cannot assign requested address
[2023-07-12 06:21:54,409] {local_task_job.py:146} INFO - Task exited with return code 1
