[2023-07-11 17:05:37,524] {taskinstance.py:877} INFO - Dependencies all met for <TaskInstance: online_payment_dag.unzip_file 2023-07-11T17:01:19.176602+00:00 [queued]>
[2023-07-11 17:05:37,582] {taskinstance.py:877} INFO - Dependencies all met for <TaskInstance: online_payment_dag.unzip_file 2023-07-11T17:01:19.176602+00:00 [queued]>
[2023-07-11 17:05:37,582] {taskinstance.py:1068} INFO - 
--------------------------------------------------------------------------------
[2023-07-11 17:05:37,583] {taskinstance.py:1069} INFO - Starting attempt 1 of 1
[2023-07-11 17:05:37,584] {taskinstance.py:1070} INFO - 
--------------------------------------------------------------------------------
[2023-07-11 17:05:37,671] {taskinstance.py:1089} INFO - Executing <Task(_PythonDecoratedOperator): unzip_file> on 2023-07-11T17:01:19.176602+00:00
[2023-07-11 17:05:37,680] {standard_task_runner.py:52} INFO - Started process 61 to run task
[2023-07-11 17:05:37,684] {standard_task_runner.py:76} INFO - Running: ['airflow', 'tasks', 'run', 'online_payment_dag', 'unzip_file', '2023-07-11T17:01:19.176602+00:00', '--job-id', '12', '--pool', 'default_pool', '--raw', '--subdir', 'DAGS_FOLDER/online_payment_dag.py', '--cfg-path', '/tmp/tmp_9aq4js6', '--error-file', '/tmp/tmpezoiavdw']
[2023-07-11 17:05:37,686] {standard_task_runner.py:77} INFO - Job 12: Subtask unzip_file
[2023-07-11 17:05:37,796] {logging_mixin.py:104} INFO - Running <TaskInstance: online_payment_dag.unzip_file 2023-07-11T17:01:19.176602+00:00 [running]> on host 108192df2b59
[2023-07-11 17:05:37,887] {taskinstance.py:1281} INFO - Exporting the following env vars:
AIRFLOW_CTX_DAG_EMAIL=datokza@gmail.com
AIRFLOW_CTX_DAG_OWNER=okza
AIRFLOW_CTX_DAG_ID=online_payment_dag
AIRFLOW_CTX_TASK_ID=unzip_file
AIRFLOW_CTX_EXECUTION_DATE=2023-07-11T17:01:19.176602+00:00
AIRFLOW_CTX_DAG_RUN_ID=manual__2023-07-11T17:01:19.176602+00:00
[2023-07-11 17:05:37,888] {taskinstance.py:1482} ERROR - Task failed with exception
Traceback (most recent call last):
  File "/home/airflow/.local/lib/python3.8/site-packages/airflow/models/taskinstance.py", line 1138, in _run_raw_task
    self._prepare_and_execute_task_with_callbacks(context, task)
  File "/home/airflow/.local/lib/python3.8/site-packages/airflow/models/taskinstance.py", line 1311, in _prepare_and_execute_task_with_callbacks
    result = self._execute_task(context, task_copy)
  File "/home/airflow/.local/lib/python3.8/site-packages/airflow/models/taskinstance.py", line 1341, in _execute_task
    result = task_copy.execute(context=context)
  File "/home/airflow/.local/lib/python3.8/site-packages/airflow/operators/python.py", line 233, in execute
    return_value = self.python_callable(*self.op_args, **self.op_kwargs)
  File "/opt/airflow/dags/online_payment_dag.py", line 45, in unzip_file
    with zipfile.ZipFile('{DATA_PATH}/online_payment.zip', 'r') as zip_ref:
  File "/usr/local/lib/python3.8/zipfile.py", line 1251, in __init__
    self.fp = io.open(file, filemode)
FileNotFoundError: [Errno 2] No such file or directory: '{DATA_PATH}/online_payment.zip'
[2023-07-11 17:05:37,901] {taskinstance.py:1525} INFO - Marking task as FAILED. dag_id=online_payment_dag, task_id=unzip_file, execution_date=20230711T170119, start_date=20230711T170537, end_date=20230711T170537
[2023-07-11 17:05:37,926] {configuration.py:352} WARNING - section/key [smtp/smtp_user] not found in config
[2023-07-11 17:05:37,927] {email.py:184} INFO - Email alerting: attempt 1
[2023-07-11 17:05:37,929] {configuration.py:352} WARNING - section/key [smtp/smtp_user] not found in config
[2023-07-11 17:05:37,929] {email.py:184} INFO - Email alerting: attempt 1
[2023-07-11 17:05:37,931] {taskinstance.py:1538} ERROR - Failed to send email to: datokza@gmail.com
[2023-07-11 17:05:37,931] {taskinstance.py:1539} ERROR - [Errno 99] Cannot assign requested address
Traceback (most recent call last):
  File "/home/airflow/.local/lib/python3.8/site-packages/airflow/models/taskinstance.py", line 1138, in _run_raw_task
    self._prepare_and_execute_task_with_callbacks(context, task)
  File "/home/airflow/.local/lib/python3.8/site-packages/airflow/models/taskinstance.py", line 1311, in _prepare_and_execute_task_with_callbacks
    result = self._execute_task(context, task_copy)
  File "/home/airflow/.local/lib/python3.8/site-packages/airflow/models/taskinstance.py", line 1341, in _execute_task
    result = task_copy.execute(context=context)
  File "/home/airflow/.local/lib/python3.8/site-packages/airflow/operators/python.py", line 233, in execute
    return_value = self.python_callable(*self.op_args, **self.op_kwargs)
  File "/opt/airflow/dags/online_payment_dag.py", line 45, in unzip_file
    with zipfile.ZipFile('{DATA_PATH}/online_payment.zip', 'r') as zip_ref:
  File "/usr/local/lib/python3.8/zipfile.py", line 1251, in __init__
    self.fp = io.open(file, filemode)
FileNotFoundError: [Errno 2] No such file or directory: '{DATA_PATH}/online_payment.zip'

During handling of the above exception, another exception occurred:

Traceback (most recent call last):
  File "/home/airflow/.local/lib/python3.8/site-packages/airflow/models/taskinstance.py", line 1881, in email_alert
    send_email(self.task.email, subject, html_content)
  File "/home/airflow/.local/lib/python3.8/site-packages/airflow/utils/email.py", line 52, in send_email
    return backend(
  File "/home/airflow/.local/lib/python3.8/site-packages/airflow/utils/email.py", line 97, in send_email_smtp
    send_mime_email(e_from=smtp_mail_from, e_to=recipients, mime_msg=msg, dryrun=dryrun)
  File "/home/airflow/.local/lib/python3.8/site-packages/airflow/utils/email.py", line 186, in send_mime_email
    conn = _get_smtp_connection(smtp_host, smtp_port, smtp_timeout, smtp_ssl)
  File "/home/airflow/.local/lib/python3.8/site-packages/airflow/utils/email.py", line 220, in _get_smtp_connection
    else smtplib.SMTP(host=host, port=port, timeout=timeout)
  File "/usr/local/lib/python3.8/smtplib.py", line 255, in __init__
    (code, msg) = self.connect(host, port)
  File "/usr/local/lib/python3.8/smtplib.py", line 339, in connect
    self.sock = self._get_socket(host, port, self.timeout)
  File "/usr/local/lib/python3.8/smtplib.py", line 310, in _get_socket
    return socket.create_connection((host, port), timeout,
  File "/usr/local/lib/python3.8/socket.py", line 808, in create_connection
    raise err
  File "/usr/local/lib/python3.8/socket.py", line 796, in create_connection
    sock.connect(sa)
OSError: [Errno 99] Cannot assign requested address

During handling of the above exception, another exception occurred:

Traceback (most recent call last):
  File "/home/airflow/.local/lib/python3.8/site-packages/airflow/models/taskinstance.py", line 1536, in handle_failure
    self.email_alert(error)
  File "/home/airflow/.local/lib/python3.8/site-packages/airflow/models/taskinstance.py", line 1883, in email_alert
    send_email(self.task.email, subject, html_content_err)
  File "/home/airflow/.local/lib/python3.8/site-packages/airflow/utils/email.py", line 52, in send_email
    return backend(
  File "/home/airflow/.local/lib/python3.8/site-packages/airflow/utils/email.py", line 97, in send_email_smtp
    send_mime_email(e_from=smtp_mail_from, e_to=recipients, mime_msg=msg, dryrun=dryrun)
  File "/home/airflow/.local/lib/python3.8/site-packages/airflow/utils/email.py", line 186, in send_mime_email
    conn = _get_smtp_connection(smtp_host, smtp_port, smtp_timeout, smtp_ssl)
  File "/home/airflow/.local/lib/python3.8/site-packages/airflow/utils/email.py", line 220, in _get_smtp_connection
    else smtplib.SMTP(host=host, port=port, timeout=timeout)
  File "/usr/local/lib/python3.8/smtplib.py", line 255, in __init__
    (code, msg) = self.connect(host, port)
  File "/usr/local/lib/python3.8/smtplib.py", line 339, in connect
    self.sock = self._get_socket(host, port, self.timeout)
  File "/usr/local/lib/python3.8/smtplib.py", line 310, in _get_socket
    return socket.create_connection((host, port), timeout,
  File "/usr/local/lib/python3.8/socket.py", line 808, in create_connection
    raise err
  File "/usr/local/lib/python3.8/socket.py", line 796, in create_connection
    sock.connect(sa)
OSError: [Errno 99] Cannot assign requested address
[2023-07-11 17:05:38,020] {local_task_job.py:146} INFO - Task exited with return code 1
